2016-08-01 17:00:10,124__caught_errors__ERROR__engine_logging.py__95__[Errno 2] No such file or directory: '/home/artem/Documents/PyCharm/compressor_site/media/gas_dynamics/User/Project/some_task/mean_radius'
2016-08-01 17:02:17,252__caught_errors__ERROR__engine_logging.py__95__[Errno 2] No such file or directory: '/home/artem/Documents/PyCharm/compressor_site/media/gas_dynamics/User/Project/some_task/mean_radius'
2016-08-01 17:03:30,689__caught_errors__ERROR__engine_logging.py__95__[Errno 2] No such file or directory: '/home/artem/Documents/PyCharm/compressor_site/media/gas_dynamics/User/Project/some_task/mean_radius'
2016-08-01 17:04:02,935__caught_errors__ERROR__engine_logging.py__95__[Errno 2] No such file or directory: '/home/artem/Documents/PyCharm/compressor_site/media/gas_dynamics/User/Project/some_task/mean_radius'
2016-08-01 17:04:47,262__caught_errors__ERROR__engine_logging.py__95__[Errno 2] No such file or directory: '/home/artem/Documents/PyCharm/compressor_site/media/gas_dynamics/User/Project/some_task/mean_radius'
2016-08-01 17:05:01,833__caught_errors__ERROR__engine_logging.py__95__[Errno 2] No such file or directory: '/home/artem/Documents/PyCharm/compressor_site/media/gas_dynamics/User/Project/some_task/mean_radius'
2016-08-01 17:06:27,916__caught_errors__ERROR__engine_logging.py__95__[Errno 2] No such file or directory: '/home/artem/Documents/PyCharm/compressor_site/media/gas_dynamics/User/Project/some_task/mean_radius'
2016-08-01 17:08:54,996__caught_errors__ERROR__engine_logging.py__95__[Errno 2] No such file or directory: '/home/artem/Documents/PyCharm/compressor_site/media/gas_dynamics/User/Project/some_task/mean_radius'
2016-08-01 17:10:01,814__caught_errors__ERROR__engine_logging.py__95__[Errno 2] No such file or directory: '/home/artem/Documents/PyCharm/compressor_site/media/gas_dynamics/User/Project/some_task/mean_radius'
2016-08-01 17:11:08,129__caught_errors__ERROR__engine_logging.py__95__[Errno 2] No such file or directory: '/home/artem/Documents/PyCharm/compressor_site/media/gas_dynamics/User/Project/some_task/mean_radius'
2016-08-01 17:11:52,561__caught_errors__ERROR__engine_logging.py__95__[Errno 2] No such file or directory: '/home/artem/Documents/PyCharm/compressor_site/media/gas_dynamics/User/Project/some_task/mean_radius'
2016-08-01 17:12:18,559__caught_errors__ERROR__engine_logging.py__95__[Errno 2] No such file or directory: '/home/artem/Documents/PyCharm/compressor_site/media/gas_dynamics/User/Project/some_task/mean_radius'
2016-08-01 17:12:39,583__caught_errors__ERROR__engine_logging.py__95__[Errno 2] No such file or directory: '/home/artem/Documents/PyCharm/compressor_site/media/gas_dynamics/User/Project/some_task/mean_radius'
2016-08-01 17:13:05,274__caught_errors__ERROR__engine_logging.py__95__[Errno 2] No such file or directory: '/home/artem/Documents/PyCharm/compressor_site/media/gas_dynamics/User/Project/some_task/mean_radius'
2016-08-01 17:20:28,149__caught_errors__ERROR__engine_logging.py__95__[Errno 2] No such file or directory: '/home/artem/Documents/PyCharm/compressor_site/media/gas_dynamics/User/Project/some_task/mean_radius'
2016-08-01 17:20:28,156__default_logger__ERROR__engine_logging.py__109__Valid solutions not found  File "/usr/lib/python3.5/threading.py", line 882, in _bootstrap
    self._bootstrap_inner()
  File "/usr/lib/python3.5/threading.py", line 914, in _bootstrap_inner
    self.run()
  File "/usr/lib/python3.5/threading.py", line 862, in run
    self._target(*self._args, **self._kwargs)
  File "/usr/lib/python3.5/socketserver.py", line 625, in process_request_thread
    self.finish_request(request, client_address)
  File "/usr/lib/python3.5/socketserver.py", line 354, in finish_request
    self.RequestHandlerClass(request, client_address, self)
  File "/usr/local/lib/python3.5/dist-packages/django/core/servers/basehttp.py", line 99, in __init__
    super(WSGIRequestHandler, self).__init__(*args, **kwargs)
  File "/usr/lib/python3.5/socketserver.py", line 681, in __init__
    self.handle()
  File "/usr/local/lib/python3.5/dist-packages/django/core/servers/basehttp.py", line 179, in handle
    handler.run(self.server.get_app())
  File "/usr/lib/python3.5/wsgiref/handlers.py", line 137, in run
    self.result = application(self.environ, self.start_response)
  File "/usr/local/lib/python3.5/dist-packages/django/contrib/staticfiles/handlers.py", line 63, in __call__
    return self.application(environ, start_response)
  File "/usr/local/lib/python3.5/dist-packages/django/core/handlers/wsgi.py", line 177, in __call__
    response = self.get_response(request)
  File "/usr/local/lib/python3.5/dist-packages/django/core/handlers/base.py", line 147, in get_response
    response = wrapped_callback(request, *callback_args, **callback_kwargs)
  File "/usr/local/lib/python3.5/dist-packages/django/views/generic/base.py", line 68, in view
    return self.dispatch(request, *args, **kwargs)
  File "/usr/local/lib/python3.5/dist-packages/django/views/generic/base.py", line 88, in dispatch
    return handler(request, *args, **kwargs)
  File "/home/artem/Documents/PyCharm/compressor_site/gas_dynamics/views.py", line 285, in post
    result_msg = self._calculate(solver, calc_type)
  File "/home/artem/Documents/PyCharm/compressor_site/gas_dynamics/views.py", line 346, in _calculate
    result_flags = call_func(solver)
  File "/home/artem/Documents/PyCharm/compressor_site/gas_dynamics/views.py", line 301, in call_func
    return solver.calculate_mean_radius()
  File "/home/artem/Documents/PyCharm/compressor_site/gas_dynamics/compressor_engine_handle.py", line 193, in calculate_mean_radius
    raise OperationFailedError('Valid solutions not found')
  File "/home/artem/Documents/PyCharm/compressor_site/gas_dynamics/compressor_engine_handle.py", line 47, in __init__
    traceback_ = functools.reduce(lambda x, y: x + y, traceback.format_list(traceback.extract_stack()), '')

2016-08-01 17:21:04,310__caught_errors__ERROR__engine_logging.py__95__[Errno 2] No such file or directory: '/home/artem/Documents/PyCharm/compressor_site/media/gas_dynamics/User/Project/some_task/mean_radius'
2016-08-01 17:21:04,322__default_logger__ERROR__engine_logging.py__109__Valid solutions not found  File "/usr/lib/python3.5/threading.py", line 882, in _bootstrap
    self._bootstrap_inner()
  File "/usr/lib/python3.5/threading.py", line 914, in _bootstrap_inner
    self.run()
  File "/usr/lib/python3.5/threading.py", line 862, in run
    self._target(*self._args, **self._kwargs)
  File "/usr/lib/python3.5/socketserver.py", line 625, in process_request_thread
    self.finish_request(request, client_address)
  File "/usr/lib/python3.5/socketserver.py", line 354, in finish_request
    self.RequestHandlerClass(request, client_address, self)
  File "/usr/local/lib/python3.5/dist-packages/django/core/servers/basehttp.py", line 99, in __init__
    super(WSGIRequestHandler, self).__init__(*args, **kwargs)
  File "/usr/lib/python3.5/socketserver.py", line 681, in __init__
    self.handle()
  File "/usr/local/lib/python3.5/dist-packages/django/core/servers/basehttp.py", line 179, in handle
    handler.run(self.server.get_app())
  File "/usr/lib/python3.5/wsgiref/handlers.py", line 137, in run
    self.result = application(self.environ, self.start_response)
  File "/usr/local/lib/python3.5/dist-packages/django/contrib/staticfiles/handlers.py", line 63, in __call__
    return self.application(environ, start_response)
  File "/usr/local/lib/python3.5/dist-packages/django/core/handlers/wsgi.py", line 177, in __call__
    response = self.get_response(request)
  File "/usr/local/lib/python3.5/dist-packages/django/core/handlers/base.py", line 147, in get_response
    response = wrapped_callback(request, *callback_args, **callback_kwargs)
  File "/usr/local/lib/python3.5/dist-packages/django/views/generic/base.py", line 68, in view
    return self.dispatch(request, *args, **kwargs)
  File "/usr/local/lib/python3.5/dist-packages/django/views/generic/base.py", line 88, in dispatch
    return handler(request, *args, **kwargs)
  File "/home/artem/Documents/PyCharm/compressor_site/gas_dynamics/views.py", line 285, in post
    result_msg = self._calculate(solver, calc_type)
  File "/home/artem/Documents/PyCharm/compressor_site/gas_dynamics/views.py", line 346, in _calculate
    result_flags = call_func(solver)
  File "/home/artem/Documents/PyCharm/compressor_site/gas_dynamics/views.py", line 301, in call_func
    return solver.calculate_mean_radius()
  File "/home/artem/Documents/PyCharm/compressor_site/gas_dynamics/compressor_engine_handle.py", line 189, in calculate_mean_radius
    raise OperationFailedError('Valid solutions not found')
  File "/home/artem/Documents/PyCharm/compressor_site/gas_dynamics/compressor_engine_handle.py", line 46, in __init__
    traceback_ = functools.reduce(lambda x, y: x + y, traceback.format_list(traceback.extract_stack()), '')

2016-08-01 17:22:24,275__caught_errors__ERROR__engine_logging.py__95__[Errno 2] No such file or directory: '/home/artem/Documents/PyCharm/compressor_site/media/gas_dynamics/User/Project/some_task/mean_radius'
2016-08-01 17:22:24,283__default_logger__ERROR__engine_logging.py__109__Valid solutions not found
2016-08-01 17:23:20,017__caught_errors__ERROR__engine_logging.py__109__Profiling data block not set
2016-08-01 17:23:20,019__default_logger__ERROR__engine_logging.py__109__Profiling data block not set
2016-08-02 15:38:55,839__caught_errors__ERROR__engine_logging.py__95__[Errno 2] No such file or directory: '/home/artem/Documents/PyCharm/compressor_site/media/gas_dynamics/User/Project/initialized_task/profiling'
2016-08-02 15:38:55,848__profiling__DEBUG__engine_logging.py__98__Profiled 1 of 1.
2016-08-02 15:38:55,848__profiling__DEBUG__engine_logging.py__98__Time took: 0.0082
2016-08-02 20:55:36,423__default_logger__ERROR__engine_logging.py__109__Valid solutions not found
2016-08-02 20:56:46,968__default_logger__ERROR__engine_logging.py__109__Valid solutions not found
2016-08-02 20:57:36,293__caught_errors__ERROR__engine_logging.py__95__[Errno 2] No such file or directory: '/home/artem/Documents/PyCharm/compressor_site/media/gas_dynamics/User/Project/initialized_task/mean_radius'
